2022-01-28 09:54:53,842 INFO    MainThread:16305 [wandb_setup.py:_flush():69] setting env: {}
2022-01-28 09:54:53,842 INFO    MainThread:16305 [wandb_setup.py:_flush():69] setting login settings: {}
2022-01-28 09:54:53,842 INFO    MainThread:16305 [wandb_init.py:_log_setup():334] Logging user logs to /Users/gdegournay/PycharmProjects/Udacity/MLOps/MLOps_ex/reproducible_workflow/exercices/lesson-2-data-exploration-and-preparation/exercises/exercise_4/starter/wandb/run-20220128_095453-3vqud5z2/logs/debug.log
2022-01-28 09:54:53,842 INFO    MainThread:16305 [wandb_init.py:_log_setup():335] Logging internal logs to /Users/gdegournay/PycharmProjects/Udacity/MLOps/MLOps_ex/reproducible_workflow/exercices/lesson-2-data-exploration-and-preparation/exercises/exercise_4/starter/wandb/run-20220128_095453-3vqud5z2/logs/debug-internal.log
2022-01-28 09:54:53,843 INFO    MainThread:16305 [wandb_init.py:_jupyter_setup():285] configuring jupyter hooks <wandb.sdk.wandb_init._WandbInit object at 0x19fb7f520>
2022-01-28 09:54:53,843 INFO    MainThread:16305 [wandb_init.py:init():367] calling init triggers
2022-01-28 09:54:53,843 INFO    MainThread:16305 [wandb_init.py:init():372] wandb.init called with sweep_config: {}
config: {}
2022-01-28 09:54:53,843 INFO    MainThread:16305 [wandb_init.py:init():387] re-initializing run, found existing run on stack: 1tpd51ru
2022-01-28 09:54:53,844 INFO    MainThread:16305 [wandb_run.py:finish():1135] finishing run geodego/exercise_4/1tpd51ru
2022-01-28 09:54:53,845 INFO    MainThread:16305 [wandb_run.py:_atexit_cleanup():1446] got exitcode: 0
2022-01-28 09:54:53,845 INFO    MainThread:16305 [wandb_run.py:_restore():1418] restore
2022-01-28 09:54:54,203 INFO    MainThread:16305 [wandb_run.py:_wait_for_finish():1568] got exit ret: file_counts {
  wandb_count: 1
}
pusher_stats {
  uploaded_bytes: 776
  total_bytes: 776
}

2022-01-28 09:54:56,212 INFO    MainThread:16305 [wandb_run.py:_wait_for_finish():1568] got exit ret: done: true
exit_result {
}
file_counts {
  wandb_count: 5
}
pusher_stats {
  uploaded_bytes: 5016
  total_bytes: 5016
}

2022-01-28 09:54:57,292 INFO    MainThread:16305 [wandb_run.py:_show_files():1790] logging synced files
2022-01-28 09:54:57,299 INFO    MainThread:16305 [wandb_init.py:init():416] starting backend
2022-01-28 09:54:57,299 INFO    MainThread:16305 [backend.py:_multiprocessing_setup():69] multiprocessing start_methods=spawn,fork,forkserver, using: spawn
2022-01-28 09:54:57,303 INFO    MainThread:16305 [backend.py:ensure_launched():123] starting backend process...
2022-01-28 09:54:57,307 INFO    MainThread:16305 [backend.py:ensure_launched():127] started backend process with pid: 19040
2022-01-28 09:54:57,310 INFO    MainThread:16305 [wandb_init.py:init():421] backend started and connected
2022-01-28 09:54:57,325 INFO    MainThread:16305 [wandb_init.py:init():461] updated telemetry
2022-01-28 09:54:57,325 INFO    MainThread:16305 [wandb_init.py:init():480] communicating current version
2022-01-28 09:54:57,982 INFO    MainThread:16305 [wandb_init.py:init():485] got version response upgrade_message: "wandb version 0.12.9 is available!  To upgrade, please run:\n $ pip install wandb --upgrade"

2022-01-28 09:54:57,983 INFO    MainThread:16305 [wandb_init.py:init():493] communicating run to backend with 30 second timeout
2022-01-28 09:54:58,352 INFO    MainThread:16305 [wandb_init.py:init():518] starting run threads in backend
2022-01-28 09:54:58,372 INFO    MainThread:16305 [wandb_run.py:_console_start():1476] atexit reg
2022-01-28 09:54:58,373 INFO    MainThread:16305 [wandb_run.py:_redirect():1339] redirect: SettingsConsole.WRAP
2022-01-28 09:54:58,373 INFO    MainThread:16305 [wandb_run.py:_redirect():1374] Wrapping output streams.
2022-01-28 09:54:58,373 INFO    MainThread:16305 [wandb_run.py:_redirect():1390] Redirects installed.
2022-01-28 09:54:58,373 INFO    MainThread:16305 [wandb_init.py:init():542] run started, returning control to user process
2022-01-28 09:54:58,374 INFO    MainThread:16305 [wandb_init.py:_pause_backend():247] pausing backend
2022-01-28 09:54:58,374 INFO    MainThread:16305 [jupyter.py:save_ipynb():268] looking for notebook: EDA.ipynb
2022-01-28 09:54:58,637 INFO    MainThread:16305 [wandb_init.py:_pause_backend():251] saved code: <wandb.sdk.wandb_artifacts.Artifact object at 0x19fb3f700>
2022-01-28 10:48:53,655 INFO    MainThread:16305 [wandb_init.py:_resume_backend():256] resuming backend
2022-01-28 10:48:55,172 INFO    MainThread:16305 [wandb_init.py:_pause_backend():247] pausing backend
2022-01-28 10:48:55,172 INFO    MainThread:16305 [jupyter.py:save_ipynb():268] looking for notebook: EDA.ipynb
2022-01-28 10:48:55,466 INFO    MainThread:16305 [wandb_init.py:_pause_backend():251] saved code: <wandb.sdk.wandb_artifacts.Artifact object at 0x19fb3f820>
2022-01-28 10:49:04,266 INFO    MainThread:16305 [wandb_init.py:_resume_backend():256] resuming backend
2022-01-28 10:49:04,266 INFO    MainThread:16305 [wandb_init.py:_pause_backend():247] pausing backend
2022-01-28 10:49:04,266 INFO    MainThread:16305 [jupyter.py:save_ipynb():268] looking for notebook: EDA.ipynb
2022-01-28 10:49:04,516 INFO    MainThread:16305 [wandb_init.py:_pause_backend():251] saved code: <wandb.sdk.wandb_artifacts.Artifact object at 0x19fb88eb0>
2022-01-28 10:49:17,328 INFO    MainThread:16305 [wandb_init.py:_resume_backend():256] resuming backend
2022-01-28 10:49:17,921 INFO    MainThread:16305 [wandb_init.py:_pause_backend():247] pausing backend
2022-01-28 10:49:17,921 INFO    MainThread:16305 [jupyter.py:save_ipynb():268] looking for notebook: EDA.ipynb
2022-01-28 10:49:18,196 INFO    MainThread:16305 [wandb_init.py:_pause_backend():251] saved code: <wandb.sdk.wandb_artifacts.Artifact object at 0x19fbe30a0>
2022-01-28 10:49:32,176 INFO    MainThread:16305 [wandb_init.py:_resume_backend():256] resuming backend
2022-01-28 10:49:32,178 INFO    MainThread:16305 [wandb_init.py:_pause_backend():247] pausing backend
2022-01-28 10:49:32,178 INFO    MainThread:16305 [jupyter.py:save_ipynb():268] looking for notebook: EDA.ipynb
2022-01-28 10:49:32,466 INFO    MainThread:16305 [wandb_init.py:_pause_backend():251] saved code: <wandb.sdk.wandb_artifacts.Artifact object at 0x19fbe0220>
2022-01-28 10:49:36,832 INFO    MainThread:16305 [wandb_init.py:_resume_backend():256] resuming backend
2022-01-28 10:49:36,833 INFO    MainThread:16305 [wandb_init.py:_pause_backend():247] pausing backend
2022-01-28 10:49:36,833 INFO    MainThread:16305 [jupyter.py:save_ipynb():268] looking for notebook: EDA.ipynb
2022-01-28 10:49:37,099 INFO    MainThread:16305 [wandb_init.py:_pause_backend():251] saved code: <wandb.sdk.wandb_artifacts.Artifact object at 0x19fb8d9a0>
2022-01-28 10:49:40,234 INFO    MainThread:16305 [wandb_init.py:_resume_backend():256] resuming backend
2022-01-28 10:49:49,890 INFO    MainThread:16305 [wandb_init.py:_pause_backend():247] pausing backend
2022-01-28 10:49:49,891 INFO    MainThread:16305 [jupyter.py:save_ipynb():268] looking for notebook: EDA.ipynb
2022-01-28 10:49:50,189 INFO    MainThread:16305 [wandb_init.py:_pause_backend():251] saved code: <wandb.sdk.wandb_artifacts.Artifact object at 0x19fb6b0d0>
2022-01-28 10:51:38,207 INFO    MainThread:16305 [wandb_init.py:_resume_backend():256] resuming backend
2022-01-28 10:52:28,042 INFO    MainThread:16305 [wandb_init.py:_pause_backend():247] pausing backend
2022-01-28 10:52:28,042 INFO    MainThread:16305 [jupyter.py:save_ipynb():268] looking for notebook: EDA.ipynb
2022-01-28 10:52:28,444 INFO    MainThread:16305 [wandb_init.py:_pause_backend():251] saved code: <wandb.sdk.wandb_artifacts.Artifact object at 0x1a199ee80>
2022-01-28 10:56:17,116 INFO    MainThread:16305 [wandb_init.py:_resume_backend():256] resuming backend
2022-01-28 10:56:17,171 INFO    MainThread:16305 [wandb_init.py:_pause_backend():247] pausing backend
2022-01-28 10:56:17,171 INFO    MainThread:16305 [jupyter.py:save_ipynb():268] looking for notebook: EDA.ipynb
2022-01-28 10:56:17,480 INFO    MainThread:16305 [wandb_init.py:_pause_backend():251] saved code: <wandb.sdk.wandb_artifacts.Artifact object at 0x19fb7fc10>
2022-01-28 10:57:37,351 INFO    MainThread:16305 [wandb_init.py:_resume_backend():256] resuming backend
2022-01-28 10:57:37,366 INFO    MainThread:16305 [wandb_init.py:_pause_backend():247] pausing backend
2022-01-28 10:57:37,366 INFO    MainThread:16305 [jupyter.py:save_ipynb():268] looking for notebook: EDA.ipynb
2022-01-28 10:57:37,653 INFO    MainThread:16305 [wandb_init.py:_pause_backend():251] saved code: <wandb.sdk.wandb_artifacts.Artifact object at 0x19fb70220>
2022-01-28 11:00:28,690 INFO    MainThread:16305 [wandb_init.py:_resume_backend():256] resuming backend
2022-01-28 11:00:53,512 INFO    MainThread:16305 [wandb_init.py:_pause_backend():247] pausing backend
2022-01-28 11:00:53,512 INFO    MainThread:16305 [jupyter.py:save_ipynb():268] looking for notebook: EDA.ipynb
2022-01-28 11:00:56,766 ERROR   MainThread:16305 [retry.py:__call__():111] Retry attempt failed:
Traceback (most recent call last):
  File "/Users/gdegournay/opt/anaconda3/envs/mlflow-51a201f2a8eac0601d78afdf58767b0a4aa0f41a/lib/python3.9/site-packages/urllib3/connection.py", line 174, in _new_conn
    conn = connection.create_connection(
  File "/Users/gdegournay/opt/anaconda3/envs/mlflow-51a201f2a8eac0601d78afdf58767b0a4aa0f41a/lib/python3.9/site-packages/urllib3/util/connection.py", line 72, in create_connection
    for res in socket.getaddrinfo(host, port, family, socket.SOCK_STREAM):
  File "/Users/gdegournay/opt/anaconda3/envs/mlflow-51a201f2a8eac0601d78afdf58767b0a4aa0f41a/lib/python3.9/socket.py", line 954, in getaddrinfo
    for res in _socket.getaddrinfo(host, port, family, type, proto, flags):
socket.gaierror: [Errno 8] nodename nor servname provided, or not known

During handling of the above exception, another exception occurred:

Traceback (most recent call last):
  File "/Users/gdegournay/opt/anaconda3/envs/mlflow-51a201f2a8eac0601d78afdf58767b0a4aa0f41a/lib/python3.9/site-packages/urllib3/connectionpool.py", line 703, in urlopen
    httplib_response = self._make_request(
  File "/Users/gdegournay/opt/anaconda3/envs/mlflow-51a201f2a8eac0601d78afdf58767b0a4aa0f41a/lib/python3.9/site-packages/urllib3/connectionpool.py", line 386, in _make_request
    self._validate_conn(conn)
  File "/Users/gdegournay/opt/anaconda3/envs/mlflow-51a201f2a8eac0601d78afdf58767b0a4aa0f41a/lib/python3.9/site-packages/urllib3/connectionpool.py", line 1040, in _validate_conn
    conn.connect()
  File "/Users/gdegournay/opt/anaconda3/envs/mlflow-51a201f2a8eac0601d78afdf58767b0a4aa0f41a/lib/python3.9/site-packages/urllib3/connection.py", line 358, in connect
    conn = self._new_conn()
  File "/Users/gdegournay/opt/anaconda3/envs/mlflow-51a201f2a8eac0601d78afdf58767b0a4aa0f41a/lib/python3.9/site-packages/urllib3/connection.py", line 186, in _new_conn
    raise NewConnectionError(
urllib3.exceptions.NewConnectionError: <urllib3.connection.HTTPSConnection object at 0x1a782b160>: Failed to establish a new connection: [Errno 8] nodename nor servname provided, or not known

During handling of the above exception, another exception occurred:

Traceback (most recent call last):
  File "/Users/gdegournay/opt/anaconda3/envs/mlflow-51a201f2a8eac0601d78afdf58767b0a4aa0f41a/lib/python3.9/site-packages/requests/adapters.py", line 440, in send
    resp = conn.urlopen(
  File "/Users/gdegournay/opt/anaconda3/envs/mlflow-51a201f2a8eac0601d78afdf58767b0a4aa0f41a/lib/python3.9/site-packages/urllib3/connectionpool.py", line 785, in urlopen
    retries = retries.increment(
  File "/Users/gdegournay/opt/anaconda3/envs/mlflow-51a201f2a8eac0601d78afdf58767b0a4aa0f41a/lib/python3.9/site-packages/urllib3/util/retry.py", line 592, in increment
    raise MaxRetryError(_pool, url, error or ResponseError(cause))
urllib3.exceptions.MaxRetryError: HTTPSConnectionPool(host='api.wandb.ai', port=443): Max retries exceeded with url: /graphql (Caused by NewConnectionError('<urllib3.connection.HTTPSConnection object at 0x1a782b160>: Failed to establish a new connection: [Errno 8] nodename nor servname provided, or not known'))

During handling of the above exception, another exception occurred:

Traceback (most recent call last):
  File "/Users/gdegournay/opt/anaconda3/envs/mlflow-51a201f2a8eac0601d78afdf58767b0a4aa0f41a/lib/python3.9/site-packages/wandb/old/retry.py", line 96, in __call__
    result = self._call_fn(*args, **kwargs)
  File "/Users/gdegournay/opt/anaconda3/envs/mlflow-51a201f2a8eac0601d78afdf58767b0a4aa0f41a/lib/python3.9/site-packages/wandb/apis/public.py", line 181, in execute
    return self._client.execute(*args, **kwargs)
  File "/Users/gdegournay/opt/anaconda3/envs/mlflow-51a201f2a8eac0601d78afdf58767b0a4aa0f41a/lib/python3.9/site-packages/wandb/vendor/gql-0.2.0/gql/client.py", line 52, in execute
    result = self._get_result(document, *args, **kwargs)
  File "/Users/gdegournay/opt/anaconda3/envs/mlflow-51a201f2a8eac0601d78afdf58767b0a4aa0f41a/lib/python3.9/site-packages/wandb/vendor/gql-0.2.0/gql/client.py", line 60, in _get_result
    return self.transport.execute(document, *args, **kwargs)
  File "/Users/gdegournay/opt/anaconda3/envs/mlflow-51a201f2a8eac0601d78afdf58767b0a4aa0f41a/lib/python3.9/site-packages/wandb/vendor/gql-0.2.0/gql/transport/requests.py", line 38, in execute
    request = requests.post(self.url, **post_args)
  File "/Users/gdegournay/opt/anaconda3/envs/mlflow-51a201f2a8eac0601d78afdf58767b0a4aa0f41a/lib/python3.9/site-packages/requests/api.py", line 117, in post
    return request('post', url, data=data, json=json, **kwargs)
  File "/Users/gdegournay/opt/anaconda3/envs/mlflow-51a201f2a8eac0601d78afdf58767b0a4aa0f41a/lib/python3.9/site-packages/requests/api.py", line 61, in request
    return session.request(method=method, url=url, **kwargs)
  File "/Users/gdegournay/opt/anaconda3/envs/mlflow-51a201f2a8eac0601d78afdf58767b0a4aa0f41a/lib/python3.9/site-packages/requests/sessions.py", line 529, in request
    resp = self.send(prep, **send_kwargs)
  File "/Users/gdegournay/opt/anaconda3/envs/mlflow-51a201f2a8eac0601d78afdf58767b0a4aa0f41a/lib/python3.9/site-packages/requests/sessions.py", line 645, in send
    r = adapter.send(request, **kwargs)
  File "/Users/gdegournay/opt/anaconda3/envs/mlflow-51a201f2a8eac0601d78afdf58767b0a4aa0f41a/lib/python3.9/site-packages/requests/adapters.py", line 519, in send
    raise ConnectionError(e, request=request)
requests.exceptions.ConnectionError: HTTPSConnectionPool(host='api.wandb.ai', port=443): Max retries exceeded with url: /graphql (Caused by NewConnectionError('<urllib3.connection.HTTPSConnection object at 0x1a782b160>: Failed to establish a new connection: [Errno 8] nodename nor servname provided, or not known'))
2022-01-28 11:02:00,929 INFO    MainThread:16305 [wandb_init.py:_resume_backend():256] resuming backend
2022-01-28 11:02:00,987 INFO    MainThread:16305 [wandb_init.py:_pause_backend():247] pausing backend
2022-01-28 11:02:00,987 INFO    MainThread:16305 [jupyter.py:save_ipynb():268] looking for notebook: EDA.ipynb
2022-01-28 11:02:04,293 ERROR   MainThread:16305 [retry.py:__call__():111] Retry attempt failed:
Traceback (most recent call last):
  File "/Users/gdegournay/opt/anaconda3/envs/mlflow-51a201f2a8eac0601d78afdf58767b0a4aa0f41a/lib/python3.9/site-packages/urllib3/connection.py", line 174, in _new_conn
    conn = connection.create_connection(
  File "/Users/gdegournay/opt/anaconda3/envs/mlflow-51a201f2a8eac0601d78afdf58767b0a4aa0f41a/lib/python3.9/site-packages/urllib3/util/connection.py", line 72, in create_connection
    for res in socket.getaddrinfo(host, port, family, socket.SOCK_STREAM):
  File "/Users/gdegournay/opt/anaconda3/envs/mlflow-51a201f2a8eac0601d78afdf58767b0a4aa0f41a/lib/python3.9/socket.py", line 954, in getaddrinfo
    for res in _socket.getaddrinfo(host, port, family, type, proto, flags):
socket.gaierror: [Errno 8] nodename nor servname provided, or not known

During handling of the above exception, another exception occurred:

Traceback (most recent call last):
  File "/Users/gdegournay/opt/anaconda3/envs/mlflow-51a201f2a8eac0601d78afdf58767b0a4aa0f41a/lib/python3.9/site-packages/urllib3/connectionpool.py", line 703, in urlopen
    httplib_response = self._make_request(
  File "/Users/gdegournay/opt/anaconda3/envs/mlflow-51a201f2a8eac0601d78afdf58767b0a4aa0f41a/lib/python3.9/site-packages/urllib3/connectionpool.py", line 386, in _make_request
    self._validate_conn(conn)
  File "/Users/gdegournay/opt/anaconda3/envs/mlflow-51a201f2a8eac0601d78afdf58767b0a4aa0f41a/lib/python3.9/site-packages/urllib3/connectionpool.py", line 1040, in _validate_conn
    conn.connect()
  File "/Users/gdegournay/opt/anaconda3/envs/mlflow-51a201f2a8eac0601d78afdf58767b0a4aa0f41a/lib/python3.9/site-packages/urllib3/connection.py", line 358, in connect
    conn = self._new_conn()
  File "/Users/gdegournay/opt/anaconda3/envs/mlflow-51a201f2a8eac0601d78afdf58767b0a4aa0f41a/lib/python3.9/site-packages/urllib3/connection.py", line 186, in _new_conn
    raise NewConnectionError(
urllib3.exceptions.NewConnectionError: <urllib3.connection.HTTPSConnection object at 0x1a852d550>: Failed to establish a new connection: [Errno 8] nodename nor servname provided, or not known

During handling of the above exception, another exception occurred:

Traceback (most recent call last):
  File "/Users/gdegournay/opt/anaconda3/envs/mlflow-51a201f2a8eac0601d78afdf58767b0a4aa0f41a/lib/python3.9/site-packages/requests/adapters.py", line 440, in send
    resp = conn.urlopen(
  File "/Users/gdegournay/opt/anaconda3/envs/mlflow-51a201f2a8eac0601d78afdf58767b0a4aa0f41a/lib/python3.9/site-packages/urllib3/connectionpool.py", line 785, in urlopen
    retries = retries.increment(
  File "/Users/gdegournay/opt/anaconda3/envs/mlflow-51a201f2a8eac0601d78afdf58767b0a4aa0f41a/lib/python3.9/site-packages/urllib3/util/retry.py", line 592, in increment
    raise MaxRetryError(_pool, url, error or ResponseError(cause))
urllib3.exceptions.MaxRetryError: HTTPSConnectionPool(host='api.wandb.ai', port=443): Max retries exceeded with url: /graphql (Caused by NewConnectionError('<urllib3.connection.HTTPSConnection object at 0x1a852d550>: Failed to establish a new connection: [Errno 8] nodename nor servname provided, or not known'))

During handling of the above exception, another exception occurred:

Traceback (most recent call last):
  File "/Users/gdegournay/opt/anaconda3/envs/mlflow-51a201f2a8eac0601d78afdf58767b0a4aa0f41a/lib/python3.9/site-packages/wandb/old/retry.py", line 96, in __call__
    result = self._call_fn(*args, **kwargs)
  File "/Users/gdegournay/opt/anaconda3/envs/mlflow-51a201f2a8eac0601d78afdf58767b0a4aa0f41a/lib/python3.9/site-packages/wandb/apis/public.py", line 181, in execute
    return self._client.execute(*args, **kwargs)
  File "/Users/gdegournay/opt/anaconda3/envs/mlflow-51a201f2a8eac0601d78afdf58767b0a4aa0f41a/lib/python3.9/site-packages/wandb/vendor/gql-0.2.0/gql/client.py", line 52, in execute
    result = self._get_result(document, *args, **kwargs)
  File "/Users/gdegournay/opt/anaconda3/envs/mlflow-51a201f2a8eac0601d78afdf58767b0a4aa0f41a/lib/python3.9/site-packages/wandb/vendor/gql-0.2.0/gql/client.py", line 60, in _get_result
    return self.transport.execute(document, *args, **kwargs)
  File "/Users/gdegournay/opt/anaconda3/envs/mlflow-51a201f2a8eac0601d78afdf58767b0a4aa0f41a/lib/python3.9/site-packages/wandb/vendor/gql-0.2.0/gql/transport/requests.py", line 38, in execute
    request = requests.post(self.url, **post_args)
  File "/Users/gdegournay/opt/anaconda3/envs/mlflow-51a201f2a8eac0601d78afdf58767b0a4aa0f41a/lib/python3.9/site-packages/requests/api.py", line 117, in post
    return request('post', url, data=data, json=json, **kwargs)
  File "/Users/gdegournay/opt/anaconda3/envs/mlflow-51a201f2a8eac0601d78afdf58767b0a4aa0f41a/lib/python3.9/site-packages/requests/api.py", line 61, in request
    return session.request(method=method, url=url, **kwargs)
  File "/Users/gdegournay/opt/anaconda3/envs/mlflow-51a201f2a8eac0601d78afdf58767b0a4aa0f41a/lib/python3.9/site-packages/requests/sessions.py", line 529, in request
    resp = self.send(prep, **send_kwargs)
  File "/Users/gdegournay/opt/anaconda3/envs/mlflow-51a201f2a8eac0601d78afdf58767b0a4aa0f41a/lib/python3.9/site-packages/requests/sessions.py", line 645, in send
    r = adapter.send(request, **kwargs)
  File "/Users/gdegournay/opt/anaconda3/envs/mlflow-51a201f2a8eac0601d78afdf58767b0a4aa0f41a/lib/python3.9/site-packages/requests/adapters.py", line 519, in send
    raise ConnectionError(e, request=request)
requests.exceptions.ConnectionError: HTTPSConnectionPool(host='api.wandb.ai', port=443): Max retries exceeded with url: /graphql (Caused by NewConnectionError('<urllib3.connection.HTTPSConnection object at 0x1a852d550>: Failed to establish a new connection: [Errno 8] nodename nor servname provided, or not known'))
2022-01-28 11:02:37,081 INFO    MainThread:16305 [wandb_init.py:_resume_backend():256] resuming backend
2022-01-28 11:02:37,092 INFO    MainThread:16305 [wandb_init.py:_pause_backend():247] pausing backend
2022-01-28 11:02:37,092 INFO    MainThread:16305 [jupyter.py:save_ipynb():268] looking for notebook: EDA.ipynb
2022-01-28 11:02:40,605 ERROR   MainThread:16305 [retry.py:__call__():111] Retry attempt failed:
Traceback (most recent call last):
  File "/Users/gdegournay/opt/anaconda3/envs/mlflow-51a201f2a8eac0601d78afdf58767b0a4aa0f41a/lib/python3.9/site-packages/urllib3/connection.py", line 174, in _new_conn
    conn = connection.create_connection(
  File "/Users/gdegournay/opt/anaconda3/envs/mlflow-51a201f2a8eac0601d78afdf58767b0a4aa0f41a/lib/python3.9/site-packages/urllib3/util/connection.py", line 72, in create_connection
    for res in socket.getaddrinfo(host, port, family, socket.SOCK_STREAM):
  File "/Users/gdegournay/opt/anaconda3/envs/mlflow-51a201f2a8eac0601d78afdf58767b0a4aa0f41a/lib/python3.9/socket.py", line 954, in getaddrinfo
    for res in _socket.getaddrinfo(host, port, family, type, proto, flags):
socket.gaierror: [Errno 8] nodename nor servname provided, or not known

During handling of the above exception, another exception occurred:

Traceback (most recent call last):
  File "/Users/gdegournay/opt/anaconda3/envs/mlflow-51a201f2a8eac0601d78afdf58767b0a4aa0f41a/lib/python3.9/site-packages/urllib3/connectionpool.py", line 703, in urlopen
    httplib_response = self._make_request(
  File "/Users/gdegournay/opt/anaconda3/envs/mlflow-51a201f2a8eac0601d78afdf58767b0a4aa0f41a/lib/python3.9/site-packages/urllib3/connectionpool.py", line 386, in _make_request
    self._validate_conn(conn)
  File "/Users/gdegournay/opt/anaconda3/envs/mlflow-51a201f2a8eac0601d78afdf58767b0a4aa0f41a/lib/python3.9/site-packages/urllib3/connectionpool.py", line 1040, in _validate_conn
    conn.connect()
  File "/Users/gdegournay/opt/anaconda3/envs/mlflow-51a201f2a8eac0601d78afdf58767b0a4aa0f41a/lib/python3.9/site-packages/urllib3/connection.py", line 358, in connect
    conn = self._new_conn()
  File "/Users/gdegournay/opt/anaconda3/envs/mlflow-51a201f2a8eac0601d78afdf58767b0a4aa0f41a/lib/python3.9/site-packages/urllib3/connection.py", line 186, in _new_conn
    raise NewConnectionError(
urllib3.exceptions.NewConnectionError: <urllib3.connection.HTTPSConnection object at 0x1a904a520>: Failed to establish a new connection: [Errno 8] nodename nor servname provided, or not known

During handling of the above exception, another exception occurred:

Traceback (most recent call last):
  File "/Users/gdegournay/opt/anaconda3/envs/mlflow-51a201f2a8eac0601d78afdf58767b0a4aa0f41a/lib/python3.9/site-packages/requests/adapters.py", line 440, in send
    resp = conn.urlopen(
  File "/Users/gdegournay/opt/anaconda3/envs/mlflow-51a201f2a8eac0601d78afdf58767b0a4aa0f41a/lib/python3.9/site-packages/urllib3/connectionpool.py", line 785, in urlopen
    retries = retries.increment(
  File "/Users/gdegournay/opt/anaconda3/envs/mlflow-51a201f2a8eac0601d78afdf58767b0a4aa0f41a/lib/python3.9/site-packages/urllib3/util/retry.py", line 592, in increment
    raise MaxRetryError(_pool, url, error or ResponseError(cause))
urllib3.exceptions.MaxRetryError: HTTPSConnectionPool(host='api.wandb.ai', port=443): Max retries exceeded with url: /graphql (Caused by NewConnectionError('<urllib3.connection.HTTPSConnection object at 0x1a904a520>: Failed to establish a new connection: [Errno 8] nodename nor servname provided, or not known'))

During handling of the above exception, another exception occurred:

Traceback (most recent call last):
  File "/Users/gdegournay/opt/anaconda3/envs/mlflow-51a201f2a8eac0601d78afdf58767b0a4aa0f41a/lib/python3.9/site-packages/wandb/old/retry.py", line 96, in __call__
    result = self._call_fn(*args, **kwargs)
  File "/Users/gdegournay/opt/anaconda3/envs/mlflow-51a201f2a8eac0601d78afdf58767b0a4aa0f41a/lib/python3.9/site-packages/wandb/apis/public.py", line 181, in execute
    return self._client.execute(*args, **kwargs)
  File "/Users/gdegournay/opt/anaconda3/envs/mlflow-51a201f2a8eac0601d78afdf58767b0a4aa0f41a/lib/python3.9/site-packages/wandb/vendor/gql-0.2.0/gql/client.py", line 52, in execute
    result = self._get_result(document, *args, **kwargs)
  File "/Users/gdegournay/opt/anaconda3/envs/mlflow-51a201f2a8eac0601d78afdf58767b0a4aa0f41a/lib/python3.9/site-packages/wandb/vendor/gql-0.2.0/gql/client.py", line 60, in _get_result
    return self.transport.execute(document, *args, **kwargs)
  File "/Users/gdegournay/opt/anaconda3/envs/mlflow-51a201f2a8eac0601d78afdf58767b0a4aa0f41a/lib/python3.9/site-packages/wandb/vendor/gql-0.2.0/gql/transport/requests.py", line 38, in execute
    request = requests.post(self.url, **post_args)
  File "/Users/gdegournay/opt/anaconda3/envs/mlflow-51a201f2a8eac0601d78afdf58767b0a4aa0f41a/lib/python3.9/site-packages/requests/api.py", line 117, in post
    return request('post', url, data=data, json=json, **kwargs)
  File "/Users/gdegournay/opt/anaconda3/envs/mlflow-51a201f2a8eac0601d78afdf58767b0a4aa0f41a/lib/python3.9/site-packages/requests/api.py", line 61, in request
    return session.request(method=method, url=url, **kwargs)
  File "/Users/gdegournay/opt/anaconda3/envs/mlflow-51a201f2a8eac0601d78afdf58767b0a4aa0f41a/lib/python3.9/site-packages/requests/sessions.py", line 529, in request
    resp = self.send(prep, **send_kwargs)
  File "/Users/gdegournay/opt/anaconda3/envs/mlflow-51a201f2a8eac0601d78afdf58767b0a4aa0f41a/lib/python3.9/site-packages/requests/sessions.py", line 645, in send
    r = adapter.send(request, **kwargs)
  File "/Users/gdegournay/opt/anaconda3/envs/mlflow-51a201f2a8eac0601d78afdf58767b0a4aa0f41a/lib/python3.9/site-packages/requests/adapters.py", line 519, in send
    raise ConnectionError(e, request=request)
requests.exceptions.ConnectionError: HTTPSConnectionPool(host='api.wandb.ai', port=443): Max retries exceeded with url: /graphql (Caused by NewConnectionError('<urllib3.connection.HTTPSConnection object at 0x1a904a520>: Failed to establish a new connection: [Errno 8] nodename nor servname provided, or not known'))
2022-01-28 11:03:50,812 INFO    MainThread:16305 [wandb_init.py:_resume_backend():256] resuming backend
2022-01-28 11:03:50,813 INFO    MainThread:16305 [wandb_run.py:finish():1135] finishing run geodego/exercise_4/3vqud5z2
