wandb: Network error (ConnectionError), entering retry loop. See wandb/debug-internal.log for full traceback.
wandb: Network error resolved after 0:18:30.387463, resuming normal operation.
wandb: Network error (ConnectionError), entering retry loop. See wandb/debug-internal.log for full traceback.
[34m[1mwandb[0m: Network error (ConnectionError), entering retry loop. See /Users/gdegournay/PycharmProjects/Udacity/MLOps/MLOps_ex/reproducible_workflow/exercices/lesson-2-data-exploration-and-preparation/exercises/exercise_4/starter/wandb/run-20220128_095453-3vqud5z2/logs/debug-internal.log for full traceback.
Error in callback <function _WandbInit._pause_backend at 0x19fb6cb80> (for post_run_cell):
[34m[1mwandb[0m: Network error (ConnectionError), entering retry loop. See /Users/gdegournay/PycharmProjects/Udacity/MLOps/MLOps_ex/reproducible_workflow/exercices/lesson-2-data-exploration-and-preparation/exercises/exercise_4/starter/wandb/run-20220128_095453-3vqud5z2/logs/debug-internal.log for full traceback.
Error in callback <function _WandbInit._pause_backend at 0x19fb6cb80> (for post_run_cell):
[34m[1mwandb[0m: Network error (ConnectionError), entering retry loop. See /Users/gdegournay/PycharmProjects/Udacity/MLOps/MLOps_ex/reproducible_workflow/exercices/lesson-2-data-exploration-and-preparation/exercises/exercise_4/starter/wandb/run-20220128_095453-3vqud5z2/logs/debug-internal.log for full traceback.
Error in callback <function _WandbInit._pause_backend at 0x19fb6cb80> (for post_run_cell):
Retry attempt failed:
Traceback (most recent call last):
  File "/Users/gdegournay/opt/anaconda3/envs/mlflow-51a201f2a8eac0601d78afdf58767b0a4aa0f41a/lib/python3.9/site-packages/urllib3/connection.py", line 174, in _new_conn
    conn = connection.create_connection(
  File "/Users/gdegournay/opt/anaconda3/envs/mlflow-51a201f2a8eac0601d78afdf58767b0a4aa0f41a/lib/python3.9/site-packages/urllib3/util/connection.py", line 72, in create_connection
    for res in socket.getaddrinfo(host, port, family, socket.SOCK_STREAM):
  File "/Users/gdegournay/opt/anaconda3/envs/mlflow-51a201f2a8eac0601d78afdf58767b0a4aa0f41a/lib/python3.9/socket.py", line 954, in getaddrinfo
    for res in _socket.getaddrinfo(host, port, family, type, proto, flags):
socket.gaierror: [Errno 8] nodename nor servname provided, or not known

During handling of the above exception, another exception occurred:

Traceback (most recent call last):
  File "/Users/gdegournay/opt/anaconda3/envs/mlflow-51a201f2a8eac0601d78afdf58767b0a4aa0f41a/lib/python3.9/site-packages/urllib3/connectionpool.py", line 703, in urlopen
    httplib_response = self._make_request(
  File "/Users/gdegournay/opt/anaconda3/envs/mlflow-51a201f2a8eac0601d78afdf58767b0a4aa0f41a/lib/python3.9/site-packages/urllib3/connectionpool.py", line 386, in _make_request
    self._validate_conn(conn)
  File "/Users/gdegournay/opt/anaconda3/envs/mlflow-51a201f2a8eac0601d78afdf58767b0a4aa0f41a/lib/python3.9/site-packages/urllib3/connectionpool.py", line 1040, in _validate_conn
    conn.connect()
  File "/Users/gdegournay/opt/anaconda3/envs/mlflow-51a201f2a8eac0601d78afdf58767b0a4aa0f41a/lib/python3.9/site-packages/urllib3/connection.py", line 358, in connect
    conn = self._new_conn()
  File "/Users/gdegournay/opt/anaconda3/envs/mlflow-51a201f2a8eac0601d78afdf58767b0a4aa0f41a/lib/python3.9/site-packages/urllib3/connection.py", line 186, in _new_conn
    raise NewConnectionError(
urllib3.exceptions.NewConnectionError: <urllib3.connection.HTTPSConnection object at 0x1a876e370>: Failed to establish a new connection: [Errno 8] nodename nor servname provided, or not known

During handling of the above exception, another exception occurred:

Traceback (most recent call last):
  File "/Users/gdegournay/opt/anaconda3/envs/mlflow-51a201f2a8eac0601d78afdf58767b0a4aa0f41a/lib/python3.9/site-packages/requests/adapters.py", line 440, in send
    resp = conn.urlopen(
  File "/Users/gdegournay/opt/anaconda3/envs/mlflow-51a201f2a8eac0601d78afdf58767b0a4aa0f41a/lib/python3.9/site-packages/urllib3/connectionpool.py", line 785, in urlopen
    retries = retries.increment(
  File "/Users/gdegournay/opt/anaconda3/envs/mlflow-51a201f2a8eac0601d78afdf58767b0a4aa0f41a/lib/python3.9/site-packages/urllib3/util/retry.py", line 592, in increment
    raise MaxRetryError(_pool, url, error or ResponseError(cause))
urllib3.exceptions.MaxRetryError: HTTPSConnectionPool(host='api.wandb.ai', port=443): Max retries exceeded with url: /graphql (Caused by NewConnectionError('<urllib3.connection.HTTPSConnection object at 0x1a876e370>: Failed to establish a new connection: [Errno 8] nodename nor servname provided, or not known'))

During handling of the above exception, another exception occurred:

Traceback (most recent call last):
  File "/Users/gdegournay/opt/anaconda3/envs/mlflow-51a201f2a8eac0601d78afdf58767b0a4aa0f41a/lib/python3.9/site-packages/wandb/old/retry.py", line 96, in __call__
    result = self._call_fn(*args, **kwargs)
  File "/Users/gdegournay/opt/anaconda3/envs/mlflow-51a201f2a8eac0601d78afdf58767b0a4aa0f41a/lib/python3.9/site-packages/wandb/apis/public.py", line 181, in execute
    return self._client.execute(*args, **kwargs)
  File "/Users/gdegournay/opt/anaconda3/envs/mlflow-51a201f2a8eac0601d78afdf58767b0a4aa0f41a/lib/python3.9/site-packages/wandb/vendor/gql-0.2.0/gql/client.py", line 52, in execute
    result = self._get_result(document, *args, **kwargs)
  File "/Users/gdegournay/opt/anaconda3/envs/mlflow-51a201f2a8eac0601d78afdf58767b0a4aa0f41a/lib/python3.9/site-packages/wandb/vendor/gql-0.2.0/gql/client.py", line 60, in _get_result
    return self.transport.execute(document, *args, **kwargs)
  File "/Users/gdegournay/opt/anaconda3/envs/mlflow-51a201f2a8eac0601d78afdf58767b0a4aa0f41a/lib/python3.9/site-packages/wandb/vendor/gql-0.2.0/gql/transport/requests.py", line 38, in execute
    request = requests.post(self.url, **post_args)
  File "/Users/gdegournay/opt/anaconda3/envs/mlflow-51a201f2a8eac0601d78afdf58767b0a4aa0f41a/lib/python3.9/site-packages/requests/api.py", line 117, in post
    return request('post', url, data=data, json=json, **kwargs)
  File "/Users/gdegournay/opt/anaconda3/envs/mlflow-51a201f2a8eac0601d78afdf58767b0a4aa0f41a/lib/python3.9/site-packages/requests/api.py", line 61, in request
    return session.request(method=method, url=url, **kwargs)
  File "/Users/gdegournay/opt/anaconda3/envs/mlflow-51a201f2a8eac0601d78afdf58767b0a4aa0f41a/lib/python3.9/site-packages/requests/sessions.py", line 529, in request
    resp = self.send(prep, **send_kwargs)
  File "/Users/gdegournay/opt/anaconda3/envs/mlflow-51a201f2a8eac0601d78afdf58767b0a4aa0f41a/lib/python3.9/site-packages/requests/sessions.py", line 645, in send
    r = adapter.send(request, **kwargs)
  File "/Users/gdegournay/opt/anaconda3/envs/mlflow-51a201f2a8eac0601d78afdf58767b0a4aa0f41a/lib/python3.9/site-packages/requests/adapters.py", line 519, in send
    raise ConnectionError(e, request=request)
requests.exceptions.ConnectionError: HTTPSConnectionPool(host='api.wandb.ai', port=443): Max retries exceeded with url: /graphql (Caused by NewConnectionError('<urllib3.connection.HTTPSConnection object at 0x1a876e370>: Failed to establish a new connection: [Errno 8] nodename nor servname provided, or not known'))
[34m[1mwandb[0m: Network error (ConnectionError), entering retry loop. See /Users/gdegournay/PycharmProjects/Udacity/MLOps/MLOps_ex/reproducible_workflow/exercices/lesson-2-data-exploration-and-preparation/exercises/exercise_4/starter/wandb/run-20220128_095453-3vqud5z2/logs/debug-internal.log for full traceback.
Retry attempt failed:
Traceback (most recent call last):
  File "/Users/gdegournay/opt/anaconda3/envs/mlflow-51a201f2a8eac0601d78afdf58767b0a4aa0f41a/lib/python3.9/site-packages/urllib3/connection.py", line 174, in _new_conn
    conn = connection.create_connection(
  File "/Users/gdegournay/opt/anaconda3/envs/mlflow-51a201f2a8eac0601d78afdf58767b0a4aa0f41a/lib/python3.9/site-packages/urllib3/util/connection.py", line 72, in create_connection
    for res in socket.getaddrinfo(host, port, family, socket.SOCK_STREAM):
  File "/Users/gdegournay/opt/anaconda3/envs/mlflow-51a201f2a8eac0601d78afdf58767b0a4aa0f41a/lib/python3.9/socket.py", line 954, in getaddrinfo
    for res in _socket.getaddrinfo(host, port, family, type, proto, flags):
socket.gaierror: [Errno 8] nodename nor servname provided, or not known

During handling of the above exception, another exception occurred:

Traceback (most recent call last):
  File "/Users/gdegournay/opt/anaconda3/envs/mlflow-51a201f2a8eac0601d78afdf58767b0a4aa0f41a/lib/python3.9/site-packages/urllib3/connectionpool.py", line 703, in urlopen
    httplib_response = self._make_request(
  File "/Users/gdegournay/opt/anaconda3/envs/mlflow-51a201f2a8eac0601d78afdf58767b0a4aa0f41a/lib/python3.9/site-packages/urllib3/connectionpool.py", line 386, in _make_request
    self._validate_conn(conn)
  File "/Users/gdegournay/opt/anaconda3/envs/mlflow-51a201f2a8eac0601d78afdf58767b0a4aa0f41a/lib/python3.9/site-packages/urllib3/connectionpool.py", line 1040, in _validate_conn
    conn.connect()
  File "/Users/gdegournay/opt/anaconda3/envs/mlflow-51a201f2a8eac0601d78afdf58767b0a4aa0f41a/lib/python3.9/site-packages/urllib3/connection.py", line 358, in connect
    conn = self._new_conn()
  File "/Users/gdegournay/opt/anaconda3/envs/mlflow-51a201f2a8eac0601d78afdf58767b0a4aa0f41a/lib/python3.9/site-packages/urllib3/connection.py", line 186, in _new_conn
    raise NewConnectionError(
urllib3.exceptions.NewConnectionError: <urllib3.connection.HTTPSConnection object at 0x1a60b4eb0>: Failed to establish a new connection: [Errno 8] nodename nor servname provided, or not known

During handling of the above exception, another exception occurred:

Traceback (most recent call last):
  File "/Users/gdegournay/opt/anaconda3/envs/mlflow-51a201f2a8eac0601d78afdf58767b0a4aa0f41a/lib/python3.9/site-packages/requests/adapters.py", line 440, in send
    resp = conn.urlopen(
  File "/Users/gdegournay/opt/anaconda3/envs/mlflow-51a201f2a8eac0601d78afdf58767b0a4aa0f41a/lib/python3.9/site-packages/urllib3/connectionpool.py", line 785, in urlopen
    retries = retries.increment(
  File "/Users/gdegournay/opt/anaconda3/envs/mlflow-51a201f2a8eac0601d78afdf58767b0a4aa0f41a/lib/python3.9/site-packages/urllib3/util/retry.py", line 592, in increment
    raise MaxRetryError(_pool, url, error or ResponseError(cause))
urllib3.exceptions.MaxRetryError: HTTPSConnectionPool(host='api.wandb.ai', port=443): Max retries exceeded with url: /graphql (Caused by NewConnectionError('<urllib3.connection.HTTPSConnection object at 0x1a60b4eb0>: Failed to establish a new connection: [Errno 8] nodename nor servname provided, or not known'))

During handling of the above exception, another exception occurred:

Traceback (most recent call last):
  File "/Users/gdegournay/opt/anaconda3/envs/mlflow-51a201f2a8eac0601d78afdf58767b0a4aa0f41a/lib/python3.9/site-packages/wandb/old/retry.py", line 96, in __call__
    result = self._call_fn(*args, **kwargs)
  File "/Users/gdegournay/opt/anaconda3/envs/mlflow-51a201f2a8eac0601d78afdf58767b0a4aa0f41a/lib/python3.9/site-packages/wandb/apis/public.py", line 181, in execute
    return self._client.execute(*args, **kwargs)
  File "/Users/gdegournay/opt/anaconda3/envs/mlflow-51a201f2a8eac0601d78afdf58767b0a4aa0f41a/lib/python3.9/site-packages/wandb/vendor/gql-0.2.0/gql/client.py", line 52, in execute
    result = self._get_result(document, *args, **kwargs)
  File "/Users/gdegournay/opt/anaconda3/envs/mlflow-51a201f2a8eac0601d78afdf58767b0a4aa0f41a/lib/python3.9/site-packages/wandb/vendor/gql-0.2.0/gql/client.py", line 60, in _get_result
    return self.transport.execute(document, *args, **kwargs)
  File "/Users/gdegournay/opt/anaconda3/envs/mlflow-51a201f2a8eac0601d78afdf58767b0a4aa0f41a/lib/python3.9/site-packages/wandb/vendor/gql-0.2.0/gql/transport/requests.py", line 38, in execute
    request = requests.post(self.url, **post_args)
  File "/Users/gdegournay/opt/anaconda3/envs/mlflow-51a201f2a8eac0601d78afdf58767b0a4aa0f41a/lib/python3.9/site-packages/requests/api.py", line 117, in post
    return request('post', url, data=data, json=json, **kwargs)
  File "/Users/gdegournay/opt/anaconda3/envs/mlflow-51a201f2a8eac0601d78afdf58767b0a4aa0f41a/lib/python3.9/site-packages/requests/api.py", line 61, in request
    return session.request(method=method, url=url, **kwargs)
  File "/Users/gdegournay/opt/anaconda3/envs/mlflow-51a201f2a8eac0601d78afdf58767b0a4aa0f41a/lib/python3.9/site-packages/requests/sessions.py", line 529, in request
    resp = self.send(prep, **send_kwargs)
  File "/Users/gdegournay/opt/anaconda3/envs/mlflow-51a201f2a8eac0601d78afdf58767b0a4aa0f41a/lib/python3.9/site-packages/requests/sessions.py", line 645, in send
    r = adapter.send(request, **kwargs)
  File "/Users/gdegournay/opt/anaconda3/envs/mlflow-51a201f2a8eac0601d78afdf58767b0a4aa0f41a/lib/python3.9/site-packages/requests/adapters.py", line 519, in send
    raise ConnectionError(e, request=request)
requests.exceptions.ConnectionError: HTTPSConnectionPool(host='api.wandb.ai', port=443): Max retries exceeded with url: /graphql (Caused by NewConnectionError('<urllib3.connection.HTTPSConnection object at 0x1a60b4eb0>: Failed to establish a new connection: [Errno 8] nodename nor servname provided, or not known'))
[34m[1mwandb[0m: Network error (ConnectionError), entering retry loop. See /Users/gdegournay/PycharmProjects/Udacity/MLOps/MLOps_ex/reproducible_workflow/exercices/lesson-2-data-exploration-and-preparation/exercises/exercise_4/starter/wandb/run-20220128_095453-3vqud5z2/logs/debug-internal.log for full traceback.
Error in callback <function _WandbInit._pause_backend at 0x19fb6cb80> (for post_run_cell):
